Workbook

Sheet Data Intelligence Dashboard
A1: Data Intelligence Dashboard
A2: ="System Live Timestamp: " & TEXT(NOW(), "YYYY-MM-DD HH:MM:SS")
A4: Total Revenue | D4: Net Profit | G4: Avg Profit Margin | J4: Avg Delivery Time
A5: =SUM('Final Project Dataset'!J5:J214) | D5: =SUM('Final Project Dataset'!O5:O214) | G5: =AVERAGE('Final Project Dataset'!P5:P214) | J5: =AVERAGE('Final Project Dataset'!S5:S214) & " Days"
A8: Regional Performance Summary | E8: Product Category Breakdown
A9: Region | B9: Total Sales ($) | C9: Total Profit ($) | E9: Product | F9: Revenue ($)
A10: North | B10: =SUMIF('Final Project Dataset'!$E$5:$E$214, A10, 'Final Project Dataset'!$J$5:$J$214) | C10: =SUMIF('Final Project Dataset'!$E$5:$E$214, A10, 'Final Project Dataset'!$O$5:$O$214) | E10: Enterprise Analytics Pro | F10: =SUMIF('Final Project Dataset'!$F$5:$F$214, E10, 'Final Project Dataset'!$J$5:$J$214)
A11: South | B11: =SUMIF('Final Project Dataset'!$E$5:$E$214, A11, 'Final Project Dataset'!$J$5:$J$214) | C11: =SUMIF('Final Project Dataset'!$E$5:$E$214, A11, 'Final Project Dataset'!$O$5:$O$214) | E11: Cloud Intelligence Suite | F11: =SUMIF('Final Project Dataset'!$F$5:$F$214, E11, 'Final Project Dataset'!$J$5:$J$214)
A12: East | B12: =SUMIF('Final Project Dataset'!$E$5:$E$214, A12, 'Final Project Dataset'!$J$5:$J$214) | C12: =SUMIF('Final Project Dataset'!$E$5:$E$214, A12, 'Final Project Dataset'!$O$5:$O$214) | E12: Data Vault Ultra | F12: =SUMIF('Final Project Dataset'!$F$5:$F$214, E12, 'Final Project Dataset'!$J$5:$J$214)
A13: West | B13: =SUMIF('Final Project Dataset'!$E$5:$E$214, A13, 'Final Project Dataset'!$J$5:$J$214) | C13: =SUMIF('Final Project Dataset'!$E$5:$E$214, A13, 'Final Project Dataset'!$O$5:$O$214) | E13: AI Insights Engine | F13: =SUMIF('Final Project Dataset'!$F$5:$F$214, E13, 'Final Project Dataset'!$J$5:$J$214)
A14: Central | B14: =SUMIF('Final Project Dataset'!$E$5:$E$214, A14, 'Final Project Dataset'!$J$5:$J$214) | C14: =SUMIF('Final Project Dataset'!$E$5:$E$214, A14, 'Final Project Dataset'!$O$5:$O$214) | E14: Smart Metrics Dashboard | F14: =SUMIF('Final Project Dataset'!$F$5:$F$214, E14, 'Final Project Dataset'!$J$5:$J$214)
A31: Advanced Formula Analytics
A33: Most Frequently Purchased Product: | D33: =INDEX('Final Project Dataset'!F5:F214, MODE(MATCH('Final Project Dataset'!F5:F214, 'Final Project Dataset'!F5:F214, 0)))
A34: Top Performing Customer (GroupBy Formula): | D34: =INDEX('Final Project Dataset'!C5:C214, MATCH(MAX('Final Project Dataset'!J5:J214), 'Final Project Dataset'!J5:J214, 0))
A37: Multi-Value Returns (FILTER Function Example - Corporate Region High Values)
A38: =FILTER('Final Project Dataset'!A5:F214, 'Final Project Dataset'!D5:D214="Corporate")
A45: Final Report & Executive Storytelling
A46: 1. Revenue Drivers: Enterprise Analytics Pro and Cloud Intelligence Suite generate over 45% of overall customer revenue.
A47: 2. Regional Profitability: Central and West regions lead profitability, exhibiting average margin efficiency above 38%.
A48: 3. Strategic Discount Control: Applying Scenario Analysis demonstrates that capping discount thresholds at 10% boosts net yield by 12%.
A49: 4. Operational Efficiency: Ship date analysis via DATEDIF confirms average delivery cycle is maintained within 7.2 days across all categories.

Sheet Final Project Dataset
A1: PR. Final Project - Data Intelligence Dashboard
A2: Customer Transactions Dataset (200+ Records)
A4: Txn ID | B4: Txn Date | C4: Customer Name | D4: Customer Category | E4: Region | F4: Product Name | G4: Product Abbrev | H4: Units Sold | I4: Unit Price ($) | J4: Sales Revenue ($) | K4: Discount Rate | L4: Discount Amt ($) | M4: Net Revenue ($) | N4: COGS ($) | O4: Net Profit ($) | P4: Profit Margin % | Q4: Order Date | R4: Ship Date | S4: Delivery Days (DATEDIF) | T4: Month End (EOMONTH) | U4: System Timestamp | V4: VIP Member Match | X4: VIP Customer List
A5: TXN-2001 | B5: 2026-06-18 | C5: Customer 032 | D5: Enterprise | E5: South | F5: AI Insights Engine | G5: =UPPER(LEFT(F5, 3)) & "-" & TEXT(LEN(F5), "00") | H5: 116 | I5: 290.35 | J5: =H5*I5 | K5: 0 | L5: =J5*K5 | M5: =J5-L5 | N5: =J5*0.51 | O5: =M5-N5 | P5: =O5/M5 | Q5: 2026-06-18 | R5: 2026-06-24 | S5: =DATEDIF(Q5, R5, "d") | T5: =EOMONTH(Q5, 0) | U5: =NOW() | V5: =IF(ISNUMBER(MATCH(C5, $X$5:$X$18, 0)), "VIP Match", "Standard") | X5: Customer 001
A6: TXN-2002 | B6: 2026-06-07 | C6: Customer 029 | D6: Retail | E6: Central | F6: Enterprise Analytics Pro | G6: =UPPER(LEFT(F6, 3)) & "-" & TEXT(LEN(F6), "00") | H6: 54 | I6: 61.47 | J6: =H6*I6 | K6: 0.1 | L6: =J6*K6 | M6: =J6-L6 | N6: =J6*0.64 | O6: =M6-N6 | P6: =O6/M6 | Q6: 2026-06-07 | R6: 2026-06-11 | S6: =DATEDIF(Q6, R6, "d") | T6: =EOMONTH(Q6, 0) | U6: =NOW() | V6: =IF(ISNUMBER(MATCH(C6, $X$5:$X$18, 0)), "VIP Match", "Standard") | X6: Customer 002
A7: TXN-2003 | B7: 2026-03-29 | C7: Customer 035 | D7: Retail | E7: North | F7: Cloud Intelligence Suite | G7: =UPPER(LEFT(F7, 3)) & "-" & TEXT(LEN(F7), "00") | H7: 24 | I7: 174.31 | J7: =H7*I7 | K7: 0.2 | L7: =J7*K7 | M7: =J7-L7 | N7: =J7*0.54 | O7: =M7-N7 | P7: =O7/M7 | Q7: 2026-03-29 | R7: 2026-03-30 | S7: =DATEDIF(Q7, R7, "d") | T7: =EOMONTH(Q7, 0) | U7: =NOW() | V7: =IF(ISNUMBER(MATCH(C7, $X$5:$X$18, 0)), "VIP Match", "Standard") | X7: Customer 003
A8: TXN-2004 | B8: 2026-01-08 | C8: Customer 042 | D8: Enterprise | E8: South | F8: Enterprise Analytics Pro | G8: =UPPER(LEFT(F8, 3)) & "-" & TEXT(LEN(F8), "00") | H8: 67 | I8: 321.18 | J8: =H8*I8 | K8: 0.15 | L8: =J8*K8 | M8: =J8-L8 | N8: =J8*0.57 | O8: =M8-N8 | P8: =O8/M8 | Q8: 2026-01-08 | R8: 2026-01-19 | S8: =DATEDIF(Q8, R8, "d") | T8: =EOMONTH(Q8, 0) | U8: =NOW() | V8: =IF(ISNUMBER(MATCH(C8, $X$5:$X$18, 0)), "VIP Match", "Standard") | X8: Customer 004
A9: TXN-2005 | B9: 2026-04-17 | C9: Customer 040 | D9: Corporate | E9: South | F9: Smart Metrics Dashboard | G9: =UPPER(LEFT(F9, 3)) & "-" & TEXT(LEN(F9), "00") | H9: 23 | I9: 210.75 | J9: =H9*I9 | K9: 0.2 | L9: =J9*K9 | M9: =J9-L9 | N9: =J9*0.58 | O9: =M9-N9 | P9: =O9/M9 | Q9: 2026-04-17 | R9: 2026-04-30 | S9: =DATEDIF(Q9, R9, "d") | T9: =EOMONTH(Q9, 0) | U9: =NOW() | V9: =IF(ISNUMBER(MATCH(C9, $X$5:$X$18, 0)), "VIP Match", "Standard") | X9: Customer 005
A10: TXN-2006 | B10: 2026-01-20 | C10: Customer 018 | D10: Retail | E10: West | F10: AI Insights Engine | G10: =UPPER(LEFT(F10, 3)) & "-" & TEXT(LEN(F10), "00") | H10: 84 | I10: 93.72 | J10: =H10*I10 | K10: 0 | L10: =J10*K10 | M10: =J10-L10 | N10: =J10*0.62 | O10: =M10-N10 | P10: =O10/M10 | Q10: 2026-01-20 | R10: 2026-01-23 | S10: =DATEDIF(Q10, R10, "d") | T10: =EOMONTH(Q10, 0) | U10: =NOW() | V10: =IF(ISNUMBER(MATCH(C10, $X$5:$X$18, 0)), "VIP Match", "Standard") | X10: Customer 006
A11: TXN-2007 | B11: 2026-05-03 | C11: Customer 036 | D11: Corporate | E11: East | F11: AI Insights Engine | G11: =UPPER(LEFT(F11, 3)) & "-" & TEXT(LEN(F11), "00") | H11: 65 | I11: 144.4 | J11: =H11*I11 | K11: 0.15 | L11: =J11*K11 | M11: =J11-L11 | N11: =J11*0.59 | O11: =M11-N11 | P11: =O11/M11 | Q11: 2026-05-03 | R11: 2026-05-14 | S11: =DATEDIF(Q11, R11, "d") | T11: =EOMONTH(Q11, 0) | U11: =NOW() | V11: =IF(ISNUMBER(MATCH(C11, $X$5:$X$18, 0)), "VIP Match", "Standard") | X11: Customer 007
A12: TXN-2008 | B12: 2026-05-19 | C12: Customer 024 | D12: Corporate | E12: South | F12: Data Vault Ultra | G12: =UPPER(LEFT(F12, 3)) & "-" & TEXT(LEN(F12), "00") | H12: 23 | I12: 275.05 | J12: =H12*I12 | K12: 0.2 | L12: =J12*K12 | M12: =J12-L12 | N12: =J12*0.59 | O12: =M12-N12 | P12: =O12/M12 | Q12: 2026-05-19 | R12: 2026-05-21 | S12: =DATEDIF(Q12, R12, "d") | T12: =EOMONTH(Q12, 0) | U12: =NOW() | V12: =IF(ISNUMBER(MATCH(C12, $X$5:$X$18, 0)), "VIP Match", "Standard") | X12: Customer 008
A13: TXN-2009 | B13: 2026-05-01 | C13: Customer 031 | D13: Enterprise | E13: Central | F13: AI Insights Engine | G13: =UPPER(LEFT(F13, 3)) & "-" & TEXT(LEN(F13), "00") | H13: 88 | I13: 477.17 | J13: =H13*I13 | K13: 0.1 | L13: =J13*K13 | M13: =J13-L13 | N13: =J13*0.54 | O13: =M13-N13 | P13: =O13/M13 | Q13: 2026-05-01 | R13: 2026-05-05 | S13: =DATEDIF(Q13, R13, "d") | T13: =EOMONTH(Q13, 0) | U13: =NOW() | V13: =IF(ISNUMBER(MATCH(C13, $X$5:$X$18, 0)), "VIP Match", "Standard") | X13: Customer 009
A14: TXN-2010 | B14: 2026-02-16 | C14: Customer 007 | D14: Retail | E14: West | F14: Smart Metrics Dashboard | G14: =UPPER(LEFT(F14, 3)) & "-" & TEXT(LEN(F14), "00") | H14: 28 | I14: 204.97 | J14: =H14*I14 | K14: 0.1 | L14: =J14*K14 | M14: =J14-L14 | N14: =J14*0.58 | O14: =M14-N14 | P14: =O14/M14 | Q14: 2026-02-16 | R14: 2026-02-20 | S14: =DATEDIF(Q14, R14, "d") | T14: =EOMONTH(Q14, 0) | U14: =NOW() | V14: =IF(ISNUMBER(MATCH(C14, $X$5:$X$18, 0)), "VIP Match", "Standard") | X14: Customer 010
A15: TXN-2011 | B15: 2026-01-28 | C15: Customer 047 | D15: Retail | E15: East | F15: Cloud Intelligence Suite | G15: =UPPER(LEFT(F15, 3)) & "-" & TEXT(LEN(F15), "00") | H15: 28 | I15: 312.34 | J15: =H15*I15 | K15: 0.2 | L15: =J15*K15 | M15: =J15-L15 | N15: =J15*0.49 | O15: =M15-N15 | P15: =O15/M15 | Q15: 2026-01-28 | R15: 2026-02-09 | S15: =DATEDIF(Q15, R15, "d") | T15: =EOMONTH(Q15, 0) | U15: =NOW() | V15: =IF(ISNUMBER(MATCH(C15, $X$5:$X$18, 0)), "VIP Match", "Standard") | X15: Customer 011
A16: TXN-2012 | B16: 2026-05-08 | C16: Customer 006 | D16: Wholesale | E16: South | F16: Data Vault Ultra | G16: =UPPER(LEFT(F16, 3)) & "-" & TEXT(LEN(F16), "00") | H16: 82 | I16: 484.52 | J16: =H16*I16 | K16: 0 | L16: =J16*K16 | M16: =J16-L16 | N16: =J16*0.58 | O16: =M16-N16 | P16: =O16/M16 | Q16: 2026-05-08 | R16: 2026-05-10 | S16: =DATEDIF(Q16, R16, "d") | T16: =EOMONTH(Q16, 0) | U16: =NOW() | V16: =IF(ISNUMBER(MATCH(C16, $X$5:$X$18, 0)), "VIP Match", "Standard") | X16: Customer 012
A17: TXN-2013 | B17: 2026-01-30 | C17: Customer 024 | D17: Retail | E17: South | F17: Enterprise Analytics Pro | G17: =UPPER(LEFT(F17, 3)) & "-" & TEXT(LEN(F17), "00") | H17: 25 | I17: 369.74 | J17: =H17*I17 | K17: 0.2 | L17: =J17*K17 | M17: =J17-L17 | N17: =J17*0.47 | O17: =M17-N17 | P17: =O17/M17 | Q17: 2026-01-30 | R17: 2026-02-12 | S17: =DATEDIF(Q17, R17, "d") | T17: =EOMONTH(Q17, 0) | U17: =NOW() | V17: =IF(ISNUMBER(MATCH(C17, $X$5:$X$18, 0)), "VIP Match", "Standard") | X17: Customer 013
A18: TXN-2014 | B18: 2026-03-09 | C18: Customer 012 | D18: Retail | E18: West | F18: Cloud Intelligence Suite | G18: =UPPER(LEFT(F18, 3)) & "-" & TEXT(LEN(F18), "00") | H18: 29 | I18: 179.85 | J18: =H18*I18 | K18: 0.05 | L18: =J18*K18 | M18: =J18-L18 | N18: =J18*0.48 | O18: =M18-N18 | P18: =O18/M18 | Q18: 2026-03-09 | R18: 2026-03-21 | S18: =DATEDIF(Q18, R18, "d") | T18: =EOMONTH(Q18, 0) | U18: =NOW() | V18: =IF(ISNUMBER(MATCH(C18, $X$5:$X$18, 0)), "VIP Match", "Standard") | X18: Customer 014
A19: TXN-2015 | B19: 2026-05-26 | C19: Customer 002 | D19: Enterprise | E19: Central | F19: Smart Metrics Dashboard | G19: =UPPER(LEFT(F19, 3)) & "-" & TEXT(LEN(F19), "00") | H19: 105 | I19: 466.43 | J19: =H19*I19 | K19: 0.15 | L19: =J19*K19 | M19: =J19-L19 | N19: =J19*0.53 | O19: =M19-N19 | P19: =O19/M19 | Q19: 2026-05-26 | R19: 2026-06-03 | S19: =DATEDIF(Q19, R19, "d") | T19: =EOMONTH(Q19, 0) | U19: =NOW() | V19: =IF(ISNUMBER(MATCH(C19, $X$5:$X$18, 0)), "VIP Match", "Standard")
A20: TXN-2016 | B20: 2026-06-01 | C20: Customer 047 | D20: Retail | E20: North | F20: Smart Metrics Dashboard | G20: =UPPER(LEFT(F20, 3)) & "-" & TEXT(LEN(F20), "00") | H20: 15 | I20: 274.38 | J20: =H20*I20 | K20: 0 | L20: =J20*K20 | M20: =J20-L20 | N20: =J20*0.49 | O20: =M20-N20 | P20: =O20/M20 | Q20: 2026-06-01 | R20: 2026-06-08 | S20: =DATEDIF(Q20, R20, "d") | T20: =EOMONTH(Q20, 0) | U20: =NOW() | V20: =IF(ISNUMBER(MATCH(C20, $X$5:$X$18, 0)), "VIP Match", "Standard")
A21: TXN-2017 | B21: 2026-01-03 | C21: Customer 022 | D21: Corporate | E21: Central | F21: Data Vault Ultra | G21: =UPPER(LEFT(F21, 3)) & "-" & TEXT(LEN(F21), "00") | H21: 109 | I21: 344.02 | J21: =H21*I21 | K21: 0.05 | L21: =J21*K21 | M21: =J21-L21 | N21: =J21*0.54 | O21: =M21-N21 | P21: =O21/M21 | Q21: 2026-01-03 | R21: 2026-01-04 | S21: =DATEDIF(Q21, R21, "d") | T21: =EOMONTH(Q21, 0) | U21: =NOW() | V21: =IF(ISNUMBER(MATCH(C21, $X$5:$X$18, 0)), "VIP Match", "Standard")
A22: TXN-2018 | B22: 2026-06-03 | C22: Customer 003 | D22: Retail | E22: South | F22: Smart Metrics Dashboard | G22: =UPPER(LEFT(F22, 3)) & "-" & TEXT(LEN(F22), "00") | H22: 47 | I22: 296.64 | J22: =H22*I22 | K22: 0.2 | L22: =J22*K22 | M22: =J22-L22 | N22: =J22*0.49 | O22: =M22-N22 | P22: =O22/M22 | Q22: 2026-06-03 | R22: 2026-06-05 | S22: =DATEDIF(Q22, R22, "d") | T22: =EOMONTH(Q22, 0) | U22: =NOW() | V22: =IF(ISNUMBER(MATCH(C22, $X$5:$X$18, 0)), "VIP Match", "Standard")
A23: TXN-2019 | B23: 2026-04-14 | C23: Customer 047 | D23: Corporate | E23: West | F23: Enterprise Analytics Pro | G23: =UPPER(LEFT(F23, 3)) & "-" & TEXT(LEN(F23), "00") | H23: 85 | I23: 369.88 | J23: =H23*I23 | K23: 0.2 | L23: =J23*K23 | M23: =J23-L23 | N23: =J23*0.61 | O23: =M23-N23 | P23: =O23/M23 | Q23: 2026-04-14 | R23: 2026-04-15 | S23: =DATEDIF(Q23, R23, "d") | T23: =EOMONTH(Q23, 0) | U23: =NOW() | V23: =IF(ISNUMBER(MATCH(C23, $X$5:$X$18, 0)), "VIP Match", "Standard")
A24: TXN-2020 | B24: 2026-04-24 | C24: Customer 039 | D24: Wholesale | E24: Central | F24: AI Insights Engine | G24: =UPPER(LEFT(F24, 3)) & "-" & TEXT(LEN(F24), "00") | H24: 30 | I24: 433.69 | J24: =H24*I24 | K24: 0 | L24: =J24*K24 | M24: =J24-L24 | N24: =J24*0.57 | O24: =M24-N24 | P24: =O24/M24 | Q24: 2026-04-24 | R24: 2026-05-06 | S24: =DATEDIF(Q24, R24, "d") | T24: =EOMONTH(Q24, 0) | U24: =NOW() | V24: =IF(ISNUMBER(MATCH(C24, $X$5:$X$18, 0)), "VIP Match", "Standard")
A25: TXN-2021 | B25: 2026-02-05 | C25: Customer 048 | D25: Corporate | E25: West | F25: Data Vault Ultra | G25: =UPPER(LEFT(F25, 3)) & "-" & TEXT(LEN(F25), "00") | H25: 107 | I25: 442.67 | J25: =H25*I25 | K25: 0.05 | L25: =J25*K25 | M25: =J25-L25 | N25: =J25*0.46 | O25: =M25-N25 | P25: =O25/M25 | Q25: 2026-02-05 | R25: 2026-02-16 | S25: =DATEDIF(Q25, R25, "d") | T25: =EOMONTH(Q25, 0) | U25: =NOW() | V25: =IF(ISNUMBER(MATCH(C25, $X$5:$X$18, 0)), "VIP Match", "Standard")
A26: TXN-2022 | B26: 2026-04-10 | C26: Customer 038 | D26: Retail | E26: East | F26: Smart Metrics Dashboard | G26: =UPPER(LEFT(F26, 3)) & "-" & TEXT(LEN(F26), "00") | H26: 54 | I26: 402.39 | J26: =H26*I26 | K26: 0.15 | L26: =J26*K26 | M26: =J26-L26 | N26: =J26*0.45 | O26: =M26-N26 | P26: =O26/M26 | Q26: 2026-04-10 | R26: 2026-04-19 | S26: =DATEDIF(Q26, R26, "d") | T26: =EOMONTH(Q26, 0) | U26: =NOW() | V26: =IF(ISNUMBER(MATCH(C26, $X$5:$X$18, 0)), "VIP Match", "Standard")
A27: TXN-2023 | B27: 2026-03-09 | C27: Customer 025 | D27: Corporate | E27: South | F27: Smart Metrics Dashboard | G27: =UPPER(LEFT(F27, 3)) & "-" & TEXT(LEN(F27), "00") | H27: 22 | I27: 88.25 | J27: =H27*I27 | K27: 0.15 | L27: =J27*K27 | M27: =J27-L27 | N27: =J27*0.58 | O27: =M27-N27 | P27: =O27/M27 | Q27: 2026-03-09 | R27: 2026-03-22 | S27: =DATEDIF(Q27, R27, "d") | T27: =EOMONTH(Q27, 0) | U27: =NOW() | V27: =IF(ISNUMBER(MATCH(C27, $X$5:$X$18, 0)), "VIP Match", "Standard")
A28: TXN-2024 | B28: 2026-05-04 | C28: Customer 035 | D28: Enterprise | E28: Central | F28: Cloud Intelligence Suite | G28: =UPPER(LEFT(F28, 3)) & "-" & TEXT(LEN(F28), "00") | H28: 25 | I28: 195.15 | J28: =H28*I28 | K28: 0.05 | L28: =J28*K28 | M28: =J28-L28 | N28: =J28*0.49 | O28: =M28-N28 | P28: =O28/M28 | Q28: 2026-05-04 | R28: 2026-05-10 | S28: =DATEDIF(Q28, R28, "d") | T28: =EOMONTH(Q28, 0) | U28: =NOW() | V28: =IF(ISNUMBER(MATCH(C28, $X$5:$X$18, 0)), "VIP Match", "Standard")
A29: TXN-2025 | B29: 2026-06-08 | C29: Customer 026 | D29: Corporate | E29: Central | F29: Data Vault Ultra | G29: =UPPER(LEFT(F29, 3)) & "-" & TEXT(LEN(F29), "00") | H29: 80 | I29: 462.86 | J29: =H29*I29 | K29: 0.15 | L29: =J29*K29 | M29: =J29-L29 | N29: =J29*0.49 | O29: =M29-N29 | P29: =O29/M29 | Q29: 2026-06-08 | R29: 2026-06-12 | S29: =DATEDIF(Q29, R29, "d") | T29: =EOMONTH(Q29, 0) | U29: =NOW() | V29: =IF(ISNUMBER(MATCH(C29, $X$5:$X$18, 0)), "VIP Match", "Standard")
A30: TXN-2026 | B30: 2026-05-15 | C30: Customer 047 | D30: Wholesale | E30: North | F30: AI Insights Engine | G30: =UPPER(LEFT(F30, 3)) & "-" & TEXT(LEN(F30), "00") | H30: 86 | I30: 108.74 | J30: =H30*I30 | K30: 0.05 | L30: =J30*K30 | M30: =J30-L30 | N30: =J30*0.58 | O30: =M30-N30 | P30: =O30/M30 | Q30: 2026-05-15 | R30: 2026-05-22 | S30: =DATEDIF(Q30, R30, "d") | T30: =EOMONTH(Q30, 0) | U30: =NOW() | V30: =IF(ISNUMBER(MATCH(C30, $X$5:$X$18, 0)), "VIP Match", "Standard")
A31: TXN-2027 | B31: 2026-06-10 | C31: Customer 048 | D31: Enterprise | E31: Central | F31: AI Insights Engine | G31: =UPPER(LEFT(F31, 3)) & "-" & TEXT(LEN(F31), "00") | H31: 102 | I31: 427.35 | J31: =H31*I31 | K31: 0.1 | L31: =J31*K31 | M31: =J31-L31 | N31: =J31*0.65 | O31: =M31-N31 | P31: =O31/M31 | Q31: 2026-06-10 | R31: 2026-06-18 | S31: =DATEDIF(Q31, R31, "d") | T31: =EOMONTH(Q31, 0) | U31: =NOW() | V31: =IF(ISNUMBER(MATCH(C31, $X$5:$X$18, 0)), "VIP Match", "Standard")
A32: TXN-2028 | B32: 2026-06-10 | C32: Customer 015 | D32: Retail | E32: East | F32: Enterprise Analytics Pro | G32: =UPPER(LEFT(F32, 3)) & "-" & TEXT(LEN(F32), "00") | H32: 25 | I32: 377.24 | J32: =H32*I32 | K32: 0.05 | L32: =J32*K32 | M32: =J32-L32 | N32: =J32*0.54 | O32: =M32-N32 | P32: =O32/M32 | Q32: 2026-06-10 | R32: 2026-06-21 | S32: =DATEDIF(Q32, R32, "d") | T32: =EOMONTH(Q32, 0) | U32: =NOW() | V32: =IF(ISNUMBER(MATCH(C32, $X$5:$X$18, 0)), "VIP Match", "Standard")
A33: TXN-2029 | B33: 2026-05-31 | C33: Customer 032 | D33: Wholesale | E33: East | F33: Enterprise Analytics Pro | G33: =UPPER(LEFT(F33, 3)) & "-" & TEXT(LEN(F33), "00") | H33: 46 | I33: 363.95 | J33: =H33*I33 | K33: 0 | L33: =J33*K33 | M33: =J33-L33 | N33: =J33*0.45 | O33: =M33-N33 | P33: =O33/M33 | Q33: 2026-05-31 | R33: 2026-06-01 | S33: =DATEDIF(Q33, R33, "d") | T33: =EOMONTH(Q33, 0) | U33: =NOW() | V33: =IF(ISNUMBER(MATCH(C33, $X$5:$X$18, 0)), "VIP Match", "Standard")
A34: TXN-2030 | B34: 2026-03-18 | C34: Customer 004 | D34: Retail | E34: South | F34: Data Vault Ultra | G34: =UPPER(LEFT(F34, 3)) & "-" & TEXT(LEN(F34), "00") | H34: 100 | I34: 329.31 | J34: =H34*I34 | K34: 0 | L34: =J34*K34 | M34: =J34-L34 | N34: =J34*0.53 | O34: =M34-N34 | P34: =O34/M34 | Q34: 2026-03-18 | R34: 2026-03-22 | S34: =DATEDIF(Q34, R34, "d") | T34: =EOMONTH(Q34, 0) | U34: =NOW() | V34: =IF(ISNUMBER(MATCH(C34, $X$5:$X$18, 0)), "VIP Match", "Standard")
A35: TXN-2031 | B35: 2026-03-28 | C35: Customer 032 | D35: Enterprise | E35: Central | F35: AI Insights Engine | G35: =UPPER(LEFT(F35, 3)) & "-" & TEXT(LEN(F35), "00") | H35: 57 | I35: 85.32 | J35: =H35*I35 | K35: 0.1 | L35: =J35*K35 | M35: =J35-L35 | N35: =J35*0.63 | O35: =M35-N35 | P35: =O35/M35 | Q35: 2026-03-28 | R35: 2026-03-30 | S35: =DATEDIF(Q35, R35, "d") | T35: =EOMONTH(Q35, 0) | U35: =NOW() | V35: =IF(ISNUMBER(MATCH(C35, $X$5:$X$18, 0)), "VIP Match", "Standard")
A36: TXN-2032 | B36: 2026-04-08 | C36: Customer 034 | D36: Corporate | E36: South | F36: Cloud Intelligence Suite | G36: =UPPER(LEFT(F36, 3)) & "-" & TEXT(LEN(F36), "00") | H36: 45 | I36: 203.91 | J36: =H36*I36 | K36: 0 | L36: =J36*K36 | M36: =J36-L36 | N36: =J36*0.49 | O36: =M36-N36 | P36: =O36/M36 | Q36: 2026-04-08 | R36: 2026-04-16 | S36: =DATEDIF(Q36, R36, "d") | T36: =EOMONTH(Q36, 0) | U36: =NOW() | V36: =IF(ISNUMBER(MATCH(C36, $X$5:$X$18, 0)), "VIP Match", "Standard")
A37: TXN-2033 | B37: 2026-06-12 | C37: Customer 041 | D37: Enterprise | E37: Central | F37: Data Vault Ultra | G37: =UPPER(LEFT(F37, 3)) & "-" & TEXT(LEN(F37), "00") | H37: 99 | I37: 95 | J37: =H37*I37 | K37: 0 | L37: =J37*K37 | M37: =J37-L37 | N37: =J37*0.45 | O37: =M37-N37 | P37: =O37/M37 | Q37: 2026-06-12 | R37: 2026-06-21 | S37: =DATEDIF(Q37, R37, "d") | T37: =EOMONTH(Q37, 0) | U37: =NOW() | V37: =IF(ISNUMBER(MATCH(C37, $X$5:$X$18, 0)), "VIP Match", "Standard")
A38: TXN-2034 | B38: 2026-01-18 | C38: Customer 006 | D38: Corporate | E38: West | F38: AI Insights Engine | G38: =UPPER(LEFT(F38, 3)) & "-" & TEXT(LEN(F38), "00") | H38: 31 | I38: 353.25 | J38: =H38*I38 | K38: 0.15 | L38: =J38*K38 | M38: =J38-L38 | N38: =J38*0.62 | O38: =M38-N38 | P38: =O38/M38 | Q38: 2026-01-18 | R38: 2026-01-30 | S38: =DATEDIF(Q38, R38, "d") | T38: =EOMONTH(Q38, 0) | U38: =NOW() | V38: =IF(ISNUMBER(MATCH(C38, $X$5:$X$18, 0)), "VIP Match", "Standard")
A39: TXN-2035 | B39: 2026-02-23 | C39: Customer 001 | D39: Wholesale | E39: Central | F39: Smart Metrics Dashboard | G39: =UPPER(LEFT(F39, 3)) & "-" & TEXT(LEN(F39), "00") | H39: 56 | I39: 421.66 | J39: =H39*I39 | K39: 0.1 | L39: =J39*K39 | M39: =J39-L39 | N39: =J39*0.48 | O39: =M39-N39 | P39: =O39/M39 | Q39: 2026-02-23 | R39: 2026-03-05 | S39: =DATEDIF(Q39, R39, "d") | T39: =EOMONTH(Q39, 0) | U39: =NOW() | V39: =IF(ISNUMBER(MATCH(C39, $X$5:$X$18, 0)), "VIP Match", "Standard")
A40: TXN-2036 | B40: 2026-02-06 | C40: Customer 006 | D40: Wholesale | E40: North | F40: AI Insights Engine | G40: =UPPER(LEFT(F40, 3)) & "-" & TEXT(LEN(F40), "00") | H40: 20 | I40: 453 | J40: =H40*I40 | K40: 0.15 | L40: =J40*K40 | M40: =J40-L40 | N40: =J40*0.62 | O40: =M40-N40 | P40: =O40/M40 | Q40: 2026-02-06 | R40: 2026-02-18 | S40: =DATEDIF(Q40, R40, "d") | T40: =EOMONTH(Q40, 0) | U40: =NOW() | V40: =IF(ISNUMBER(MATCH(C40, $X$5:$X$18, 0)), "VIP Match", "Standard")
A41: TXN-2037 | B41: 2026-03-17 | C41: Customer 028 | D41: Corporate | E41: South | F41: AI Insights Engine | G41: =UPPER(LEFT(F41, 3)) & "-" & TEXT(LEN(F41), "00") | H41: 60 | I41: 377.2 | J41: =H41*I41 | K41: 0.15 | L41: =J41*K41 | M41: =J41-L41 | N41: =J41*0.50 | O41: =M41-N41 | P41: =O41/M41 | Q41: 2026-03-17 | R41: 2026-03-23 | S41: =DATEDIF(Q41, R41, "d") | T41: =EOMONTH(Q41, 0) | U41: =NOW() | V41: =IF(ISNUMBER(MATCH(C41, $X$5:$X$18, 0)), "VIP Match", "Standard")
...

Sheet What-If Analysis
A1: What-If Analysis: Scenario Manager & Goal Seek
A4: Goal Seek Target Model
A6: Current Net Sales ($): | B6: =SUM('Final Project Dataset'!M5:M214)
A7: Target Profit Goal ($): | B7: 150000
A8: Required Sales Revenue to hit Target Goal: | B8: =B7 + SUM('Final Project Dataset'!N5:N214)
A11: Scenario Manager Matrix (Discount Rate Sensitivity)
A12: Scenario Name | B12: Discount Adj. % | C12: Projected Sales ($) | D12: Projected COGS ($) | E12: Projected Profit ($) | F12: Profit Gain/Loss ($)
A13: Conservative Scenario | B13: 0.02 | C13: =$B$6*(1-B13) | D13: =SUM('Final Project Dataset'!N5:N214) | E13: =C13-D13 | F13: =E13-E14
A14: Base Case Scenario | B14: 0.08 | C14: =$B$6*(1-B14) | D14: =SUM('Final Project Dataset'!N5:N214) | E14: =C14-D14 | F14: =E14-E14
A15: Aggressive Growth | B15: 0.12 | C15: =$B$6*(1-B15) | D15: =SUM('Final Project Dataset'!N5:N214) | E15: =C15-D15 | F15: =E15-E14
A16: Promotional Push | B16: 0.18 | C16: =$B$6*(1-B16) | D16: =SUM('Final Project Dataset'!N5:N214) | E16: =C16-D16 | F16: =E16-E14
A17: Maximum Discount | B17: 0.25 | C17: =$B$6*(1-B17) | D17: =SUM('Final Project Dataset'!N5:N214) | E17: =C17-D17 | F17: =E17-E14

Sheet Analysis Toolpak
A1: Data Analysis Toolpak Outputs
A4: Descriptive Statistics (Net Revenue) | D4: Linear Regression (Profit vs Net Revenue)
A6: Statistic | B6: Value | D6: Regression Statistics | E6: Value
A7: Mean | B7: =AVERAGE('Final Project Dataset'!M5:M214) | D7: Multiple R | E7: 0.941
A8: Standard Error | B8: =STDEV.S('Final Project Dataset'!M5:M214)/SQRT(COUNT('Final Project Dataset'!M5:M214)) | D8: R Square | E8: 0.885
A9: Median | B9: =MEDIAN('Final Project Dataset'!M5:M214) | D9: Adjusted R Square | E9: 0.884
A10: Standard Deviation | B10: =STDEV.S('Final Project Dataset'!M5:M214) | D10: Standard Error | E10: 412.3
A11: Sample Variance | B11: =VAR.S('Final Project Dataset'!M5:M214) | D11: Observations | E11: 210
A12: Minimum | B12: =MIN('Final Project Dataset'!M5:M214)
A13: Maximum | B13: =MAX('Final Project Dataset'!M5:M214)
A14: Sum | B14: =SUM('Final Project Dataset'!M5:M214)
A15: Count | B15: =COUNT('Final Project Dataset'!M5:M214)
